Collecting poetry==2.1.2
  Downloading poetry-2.1.2-py3-none-any.whl.metadata (7.1 kB)
Collecting build<2.0.0,>=1.2.1 (from poetry==2.1.2)
  Downloading build-1.2.2.post1-py3-none-any.whl.metadata (6.5 kB)
Collecting cachecontrol<0.15.0,>=0.14.0 (from cachecontrol[filecache]<0.15.0,>=0.14.0->poetry==2.1.2)
  Downloading cachecontrol-0.14.2-py3-none-any.whl.metadata (3.1 kB)
Collecting cleo<3.0.0,>=2.1.0 (from poetry==2.1.2)
  Downloading cleo-2.1.0-py3-none-any.whl.metadata (12 kB)
Collecting dulwich<0.23.0,>=0.22.6 (from poetry==2.1.2)
  Downloading dulwich-0.22.8-cp312-cp312-manylinux_2_17_x86_64.manylinux2014_x86_64.whl.metadata (4.9 kB)
Collecting fastjsonschema<3.0.0,>=2.18.0 (from poetry==2.1.2)
  Downloading fastjsonschema-2.21.1-py3-none-any.whl.metadata (2.2 kB)
Collecting findpython<0.7.0,>=0.6.2 (from poetry==2.1.2)
  Downloading findpython-0.6.3-py3-none-any.whl.metadata (5.3 kB)
Collecting installer<0.8.0,>=0.7.0 (from poetry==2.1.2)
  Downloading installer-0.7.0-py3-none-any.whl.metadata (936 bytes)
Collecting keyring<26.0.0,>=25.1.0 (from poetry==2.1.2)
  Downloading keyring-25.6.0-py3-none-any.whl.metadata (20 kB)
ERROR: Exception:
Traceback (most recent call last):
  File "/home/el-mehdi-amghary/snap/code/190/.local/share/pypoetry/venv/lib/python3.12/site-packages/pip/_vendor/urllib3/response.py", line 438, in _error_catcher
    yield
  File "/home/el-mehdi-amghary/snap/code/190/.local/share/pypoetry/venv/lib/python3.12/site-packages/pip/_vendor/urllib3/response.py", line 561, in read
    data = self._fp_read(amt) if not fp_closed else b""
           ^^^^^^^^^^^^^^^^^^
  File "/home/el-mehdi-amghary/snap/code/190/.local/share/pypoetry/venv/lib/python3.12/site-packages/pip/_vendor/urllib3/response.py", line 527, in _fp_read
    return self._fp.read(amt) if amt is not None else self._fp.read()
           ^^^^^^^^^^^^^^^^^^
  File "/home/el-mehdi-amghary/snap/code/190/.local/share/pypoetry/venv/lib/python3.12/site-packages/pip/_vendor/cachecontrol/filewrapper.py", line 98, in read
    data: bytes = self.__fp.read(amt)
                  ^^^^^^^^^^^^^^^^^^^
  File "/usr/lib/python3.12/http/client.py", line 479, in read
    s = self.fp.read(amt)
        ^^^^^^^^^^^^^^^^^
  File "/usr/lib/python3.12/socket.py", line 707, in readinto
    return self._sock.recv_into(b)
           ^^^^^^^^^^^^^^^^^^^^^^^
  File "/usr/lib/python3.12/ssl.py", line 1252, in recv_into
    return self.read(nbytes, buffer)
           ^^^^^^^^^^^^^^^^^^^^^^^^^
  File "/usr/lib/python3.12/ssl.py", line 1104, in read
    return self._sslobj.read(len, buffer)
           ^^^^^^^^^^^^^^^^^^^^^^^^^^^^^^
TimeoutError: The read operation timed out

During handling of the above exception, another exception occurred:

Traceback (most recent call last):
  File "/home/el-mehdi-amghary/snap/code/190/.local/share/pypoetry/venv/lib/python3.12/site-packages/pip/_internal/cli/base_command.py", line 106, in _run_wrapper
    status = _inner_run()
             ^^^^^^^^^^^^
  File "/home/el-mehdi-amghary/snap/code/190/.local/share/pypoetry/venv/lib/python3.12/site-packages/pip/_internal/cli/base_command.py", line 97, in _inner_run
    return self.run(options, args)
           ^^^^^^^^^^^^^^^^^^^^^^^
  File "/home/el-mehdi-amghary/snap/code/190/.local/share/pypoetry/venv/lib/python3.12/site-packages/pip/_internal/cli/req_command.py", line 67, in wrapper
    return func(self, options, args)
           ^^^^^^^^^^^^^^^^^^^^^^^^^
  File "/home/el-mehdi-amghary/snap/code/190/.local/share/pypoetry/venv/lib/python3.12/site-packages/pip/_internal/commands/install.py", line 386, in run
    requirement_set = resolver.resolve(
                      ^^^^^^^^^^^^^^^^^
  File "/home/el-mehdi-amghary/snap/code/190/.local/share/pypoetry/venv/lib/python3.12/site-packages/pip/_internal/resolution/resolvelib/resolver.py", line 95, in resolve
    result = self._result = resolver.resolve(
                            ^^^^^^^^^^^^^^^^^
  File "/home/el-mehdi-amghary/snap/code/190/.local/share/pypoetry/venv/lib/python3.12/site-packages/pip/_vendor/resolvelib/resolvers.py", line 546, in resolve
    state = resolution.resolve(requirements, max_rounds=max_rounds)
            ^^^^^^^^^^^^^^^^^^^^^^^^^^^^^^^^^^^^^^^^^^^^^^^^^^^^^^^
  File "/home/el-mehdi-amghary/snap/code/190/.local/share/pypoetry/venv/lib/python3.12/site-packages/pip/_vendor/resolvelib/resolvers.py", line 427, in resolve
    failure_causes = self._attempt_to_pin_criterion(name)
                     ^^^^^^^^^^^^^^^^^^^^^^^^^^^^^^^^^^^^
  File "/home/el-mehdi-amghary/snap/code/190/.local/share/pypoetry/venv/lib/python3.12/site-packages/pip/_vendor/resolvelib/resolvers.py", line 239, in _attempt_to_pin_criterion
    criteria = self._get_updated_criteria(candidate)
               ^^^^^^^^^^^^^^^^^^^^^^^^^^^^^^^^^^^^^
  File "/home/el-mehdi-amghary/snap/code/190/.local/share/pypoetry/venv/lib/python3.12/site-packages/pip/_vendor/resolvelib/resolvers.py", line 230, in _get_updated_criteria
    self._add_to_criteria(criteria, requirement, parent=candidate)
  File "/home/el-mehdi-amghary/snap/code/190/.local/share/pypoetry/venv/lib/python3.12/site-packages/pip/_vendor/resolvelib/resolvers.py", line 173, in _add_to_criteria
    if not criterion.candidates:
           ^^^^^^^^^^^^^^^^^^^^
  File "/home/el-mehdi-amghary/snap/code/190/.local/share/pypoetry/venv/lib/python3.12/site-packages/pip/_vendor/resolvelib/structs.py", line 156, in __bool__
    return bool(self._sequence)
           ^^^^^^^^^^^^^^^^^^^^
  File "/home/el-mehdi-amghary/snap/code/190/.local/share/pypoetry/venv/lib/python3.12/site-packages/pip/_internal/resolution/resolvelib/found_candidates.py", line 174, in __bool__
    return any(self)
           ^^^^^^^^^
  File "/home/el-mehdi-amghary/snap/code/190/.local/share/pypoetry/venv/lib/python3.12/site-packages/pip/_internal/resolution/resolvelib/found_candidates.py", line 162, in <genexpr>
    return (c for c in iterator if id(c) not in self._incompatible_ids)
           ^^^^^^^^^^^^^^^^^^^^^^^^^^^^^^^^^^^^^^^^^^^^^^^^^^^^^^^^^^^^
  File "/home/el-mehdi-amghary/snap/code/190/.local/share/pypoetry/venv/lib/python3.12/site-packages/pip/_internal/resolution/resolvelib/found_candidates.py", line 53, in _iter_built
    candidate = func()
                ^^^^^^
  File "/home/el-mehdi-amghary/snap/code/190/.local/share/pypoetry/venv/lib/python3.12/site-packages/pip/_internal/resolution/resolvelib/factory.py", line 187, in _make_candidate_from_link
    base: Optional[BaseCandidate] = self._make_base_candidate_from_link(
                                    ^^^^^^^^^^^^^^^^^^^^^^^^^^^^^^^^^^^^
  File "/home/el-mehdi-amghary/snap/code/190/.local/share/pypoetry/venv/lib/python3.12/site-packages/pip/_internal/resolution/resolvelib/factory.py", line 233, in _make_base_candidate_from_link
    self._link_candidate_cache[link] = LinkCandidate(
                                       ^^^^^^^^^^^^^^
  File "/home/el-mehdi-amghary/snap/code/190/.local/share/pypoetry/venv/lib/python3.12/site-packages/pip/_internal/resolution/resolvelib/candidates.py", line 304, in __init__
    super().__init__(
  File "/home/el-mehdi-amghary/snap/code/190/.local/share/pypoetry/venv/lib/python3.12/site-packages/pip/_internal/resolution/resolvelib/candidates.py", line 159, in __init__
    self.dist = self._prepare()
                ^^^^^^^^^^^^^^^
  File "/home/el-mehdi-amghary/snap/code/190/.local/share/pypoetry/venv/lib/python3.12/site-packages/pip/_internal/resolution/resolvelib/candidates.py", line 236, in _prepare
    dist = self._prepare_distribution()
           ^^^^^^^^^^^^^^^^^^^^^^^^^^^^
  File "/home/el-mehdi-amghary/snap/code/190/.local/share/pypoetry/venv/lib/python3.12/site-packages/pip/_internal/resolution/resolvelib/candidates.py", line 315, in _prepare_distribution
    return preparer.prepare_linked_requirement(self._ireq, parallel_builds=True)
           ^^^^^^^^^^^^^^^^^^^^^^^^^^^^^^^^^^^^^^^^^^^^^^^^^^^^^^^^^^^^^^^^^^^^^
  File "/home/el-mehdi-amghary/snap/code/190/.local/share/pypoetry/venv/lib/python3.12/site-packages/pip/_internal/operations/prepare.py", line 521, in prepare_linked_requirement
    metadata_dist = self._fetch_metadata_only(req)
                    ^^^^^^^^^^^^^^^^^^^^^^^^^^^^^^
  File "/home/el-mehdi-amghary/snap/code/190/.local/share/pypoetry/venv/lib/python3.12/site-packages/pip/_internal/operations/prepare.py", line 373, in _fetch_metadata_only
    return self._fetch_metadata_using_link_data_attr(
           ^^^^^^^^^^^^^^^^^^^^^^^^^^^^^^^^^^^^^^^^^^
  File "/home/el-mehdi-amghary/snap/code/190/.local/share/pypoetry/venv/lib/python3.12/site-packages/pip/_internal/operations/prepare.py", line 393, in _fetch_metadata_using_link_data_attr
    metadata_file = get_http_url(
                    ^^^^^^^^^^^^^
  File "/home/el-mehdi-amghary/snap/code/190/.local/share/pypoetry/venv/lib/python3.12/site-packages/pip/_internal/operations/prepare.py", line 111, in get_http_url
    from_path, content_type = download(link, temp_dir.path)
                              ^^^^^^^^^^^^^^^^^^^^^^^^^^^^^
  File "/home/el-mehdi-amghary/snap/code/190/.local/share/pypoetry/venv/lib/python3.12/site-packages/pip/_internal/network/download.py", line 148, in __call__
    for chunk in chunks:
  File "/home/el-mehdi-amghary/snap/code/190/.local/share/pypoetry/venv/lib/python3.12/site-packages/pip/_internal/network/utils.py", line 65, in response_chunks
    for chunk in response.raw.stream(
  File "/home/el-mehdi-amghary/snap/code/190/.local/share/pypoetry/venv/lib/python3.12/site-packages/pip/_vendor/urllib3/response.py", line 622, in stream
    data = self.read(amt=amt, decode_content=decode_content)
           ^^^^^^^^^^^^^^^^^^^^^^^^^^^^^^^^^^^^^^^^^^^^^^^^^
  File "/home/el-mehdi-amghary/snap/code/190/.local/share/pypoetry/venv/lib/python3.12/site-packages/pip/_vendor/urllib3/response.py", line 560, in read
    with self._error_catcher():
  File "/usr/lib/python3.12/contextlib.py", line 158, in __exit__
    self.gen.throw(value)
  File "/home/el-mehdi-amghary/snap/code/190/.local/share/pypoetry/venv/lib/python3.12/site-packages/pip/_vendor/urllib3/response.py", line 443, in _error_catcher
    raise ReadTimeoutError(self._pool, None, "Read timed out.")
pip._vendor.urllib3.exceptions.ReadTimeoutError: HTTPSConnectionPool(host='files.pythonhosted.org', port=443): Read timed out.

Traceback:

  File "<stdin>", line 937, in main
  File "<stdin>", line 574, in run
  File "<stdin>", line 596, in install
  File "<stdin>", line 699, in install_poetry
  File "<stdin>", line 389, in pip
  File "<stdin>", line 386, in python
  File "<stdin>", line 379, in run
